Traceback (most recent call last):
  File "/Users/mriki/workspace/prpy/.venv/lib/python3.11/site-packages/jupyter_cache/executors/utils.py", line 58, in single_nb_execution
    executenb(
  File "/Users/mriki/workspace/prpy/.venv/lib/python3.11/site-packages/nbclient/client.py", line 1314, in execute
    return NotebookClient(nb=nb, resources=resources, km=km, **kwargs).execute()
           ^^^^^^^^^^^^^^^^^^^^^^^^^^^^^^^^^^^^^^^^^^^^^^^^^^^^^^^^^^^^^^^^^^^^^
  File "/Users/mriki/workspace/prpy/.venv/lib/python3.11/site-packages/jupyter_core/utils/__init__.py", line 165, in wrapped
    return loop.run_until_complete(inner)
           ^^^^^^^^^^^^^^^^^^^^^^^^^^^^^^
  File "/Users/mriki/.rye/py/cpython@3.11.8/lib/python3.11/asyncio/base_events.py", line 654, in run_until_complete
    return future.result()
           ^^^^^^^^^^^^^^^
  File "/Users/mriki/workspace/prpy/.venv/lib/python3.11/site-packages/nbclient/client.py", line 709, in async_execute
    await self.async_execute_cell(
  File "/Users/mriki/workspace/prpy/.venv/lib/python3.11/site-packages/nbclient/client.py", line 1062, in async_execute_cell
    await self._check_raise_for_error(cell, cell_index, exec_reply)
  File "/Users/mriki/workspace/prpy/.venv/lib/python3.11/site-packages/nbclient/client.py", line 918, in _check_raise_for_error
    raise CellExecutionError.from_cell_and_msg(cell, exec_reply_content)
nbclient.exceptions.CellExecutionError: An error occurred while executing the following cell:
------------------
# 必要なパッケージをimport
from tqdm.auto import tqdm,trange
import numpy as np
import matplotlib.pyplot as plt
try:
    import japanize_matplotlib
except:
    !pip install japanize_matplotlib
    import japanize_matplotlib
------------------

----- stderr -----
/Users/mriki/workspace/prpy/.venv/lib/python3.11/site-packages/tqdm/auto.py:21: TqdmWarning: IProgress not found. Please update jupyter and ipywidgets. See https://ipywidgets.readthedocs.io/en/stable/user_install.html
  from .autonotebook import tqdm as notebook_tqdm
----- stdout -----
zsh:1: command not found: pip
------------------

[0;31m---------------------------------------------------------------------------[0m
[0;31mModuleNotFoundError[0m                       Traceback (most recent call last)
Cell [0;32mIn[1], line 6[0m
[1;32m      5[0m [38;5;28;01mtry[39;00m:
[0;32m----> 6[0m     [38;5;28;01mimport[39;00m [38;5;21;01mjapanize_matplotlib[39;00m
[1;32m      7[0m [38;5;28;01mexcept[39;00m:

[0;31mModuleNotFoundError[0m: No module named 'japanize_matplotlib'

During handling of the above exception, another exception occurred:

[0;31mModuleNotFoundError[0m                       Traceback (most recent call last)
Cell [0;32mIn[1], line 9[0m
[1;32m      7[0m [38;5;28;01mexcept[39;00m:
[1;32m      8[0m     get_ipython()[38;5;241m.[39msystem([38;5;124m'[39m[38;5;124mpip install japanize_matplotlib[39m[38;5;124m'[39m)
[0;32m----> 9[0m     [38;5;28;01mimport[39;00m [38;5;21;01mjapanize_matplotlib[39;00m

[0;31mModuleNotFoundError[0m: No module named 'japanize_matplotlib'

