Traceback (most recent call last):
  File "/Users/mriki/workspace/prpy/.venv/lib/python3.11/site-packages/jupyter_cache/executors/utils.py", line 58, in single_nb_execution
    executenb(
  File "/Users/mriki/workspace/prpy/.venv/lib/python3.11/site-packages/nbclient/client.py", line 1314, in execute
    return NotebookClient(nb=nb, resources=resources, km=km, **kwargs).execute()
           ^^^^^^^^^^^^^^^^^^^^^^^^^^^^^^^^^^^^^^^^^^^^^^^^^^^^^^^^^^^^^^^^^^^^^
  File "/Users/mriki/workspace/prpy/.venv/lib/python3.11/site-packages/jupyter_core/utils/__init__.py", line 165, in wrapped
    return loop.run_until_complete(inner)
           ^^^^^^^^^^^^^^^^^^^^^^^^^^^^^^
  File "/Users/mriki/.rye/py/cpython@3.11.8/lib/python3.11/asyncio/base_events.py", line 654, in run_until_complete
    return future.result()
           ^^^^^^^^^^^^^^^
  File "/Users/mriki/workspace/prpy/.venv/lib/python3.11/site-packages/nbclient/client.py", line 709, in async_execute
    await self.async_execute_cell(
  File "/Users/mriki/workspace/prpy/.venv/lib/python3.11/site-packages/nbclient/client.py", line 1062, in async_execute_cell
    await self._check_raise_for_error(cell, cell_index, exec_reply)
  File "/Users/mriki/workspace/prpy/.venv/lib/python3.11/site-packages/nbclient/client.py", line 918, in _check_raise_for_error
    raise CellExecutionError.from_cell_and_msg(cell, exec_reply_content)
nbclient.exceptions.CellExecutionError: An error occurred while executing the following cell:
------------------
class Test3:
    a = "„ÇØ„É©„ÇπÂ§âÊï∞" # „ÇØ„É©„ÇπÂ§âÊï∞„ÅØ„Åì„Åì„Å´ÂÆöÁæ©„Åó„Åæ„ÅôÔºé
    def __init__(self,x="„Ç§„É≥„Çπ„Çø„É≥„ÇπÂ§âÊï∞"):
        self.x = x

    @staticmethod
    def test_static():
        print("ÈÅ©ÂΩì„Å™ÊñáÂ≠óÂàó")

    @staticmethod
    def test_static2(y):
        print(y)

    @classmethod
    def test_classmethod(cls):
        print(cls)
        print(cls.a)
        print(cls.x)

    @classmethod
    def update_classvariable(cls, new_a):
        cls.a = new_a

    

instance4 = Test3()
instance5 = Test3()
instance4.test_classmethod()
------------------

----- stdout -----
<class '__main__.Test3'>
„ÇØ„É©„ÇπÂ§âÊï∞
------------------

[0;31m---------------------------------------------------------------------------[0m
[0;31mAttributeError[0m                            Traceback (most recent call last)
Cell [0;32mIn[12], line 28[0m
[1;32m     26[0m instance4 [38;5;241m=[39m Test3()
[1;32m     27[0m instance5 [38;5;241m=[39m Test3()
[0;32m---> 28[0m [43minstance4[49m[38;5;241;43m.[39;49m[43mtest_classmethod[49m[43m([49m[43m)[49m

Cell [0;32mIn[12], line 18[0m, in [0;36mTest3.test_classmethod[0;34m(cls)[0m
[1;32m     16[0m [38;5;28mprint[39m([38;5;28mcls[39m)
[1;32m     17[0m [38;5;28mprint[39m([38;5;28mcls[39m[38;5;241m.[39ma)
[0;32m---> 18[0m [38;5;28mprint[39m([38;5;28;43mcls[39;49m[38;5;241;43m.[39;49m[43mx[49m)

[0;31mAttributeError[0m: type object 'Test3' has no attribute 'x'

